Workbook

Sheet 🏠 Cover
B5: Vector Core CFO SOLUTIONS
B6: EXECUTIVE KPI & FINANCIAL DASHBOARD | Q4 2024
B7: CFO SERVICES • CONTROLLER SERVICES • ASSET MANAGEMENT
B8: CLIENT: | C8: ='📊 Executive Dashboard'!S2 -> Enter Client Name
B9: CONFIDENTIAL — PREPARED FOR INTERNAL USE ONLY
B12: ▌ DASHBOARD NAVIGATION
C14: 📊 Executive Dashboard | G14: Main KPI overview with charts
C15: 🏢 Property Metrics | G15: DSCR, Occupancy, NOI by property
C16: ⚙️ NOI Engine | G16: Net Operating Income waterfall
C17: 📡 Forecasting | G17: 5-Year projection model
C18: 💳 Amortization | G18: Loan schedule & payment breakdown
C19: 🏗️ Capital Plan | G19: 5-Year CapEx schedule
C20: 📋 Assumptions | G20: All model inputs & drivers (blue cells)
C21: 💵 Operating Cash Flow | G21: Quarterly & annual cash flow statement
C22: 📥 Data Pulls | G22: Monthly raw data input register
C23: 🔢 Data Engine | G23: Chart data source (do not edit)
B28: Prepared by Apex CFO Solutions | Version 1.0 | April 2024 | CONFIDENTIAL

Sheet 📊 Executive Dashboard
A2: 📊 EXECUTIVE DASHBOARD | R2: CLIENT: | S2: Enter Client Name | T2: Vector Core - Live Test 1.0
A4: ▌ KEY PERFORMANCE INDICATORS — Q4 2024
B6: NET OPERATING INCOME | F6: DEBT SVC COVERAGE | J6: PORTFOLIO OCCUPANCY | N6: OPERATING CASH FLOW | R6: GROSS REVENUE | V6: NET INCOME
B10: =TEXT('⚙️ NOI Engine'!J18/1000,"$#,##0K") -> $180K | F10: =IF('⚙️ NOI Engine'!J19<0,'⚙️ NOI Engine'!J18/(-'⚙️ NOI Engine'!J19),0) -> 1.1858214 | J10: =TEXT('🏢 Property Metrics'!D12,"0.0%") -> 96.1% | N10: =TEXT('💵 Operating Cash Flow'!F14,"$#,##0K") -> $162K | R10: =TEXT('⚙️ NOI Engine'!J6/1000,"$#,##0K") -> $297K | V10: =TEXT('💵 Operating Cash Flow'!F6,"$#,##0K") -> $138K
B12: ▲ +18.4% QoQ | F12: ▲ +0.17x QoQ | J12: ▲ +2.1pp QoQ | N12: ▲ +28.6% QoQ | R12: ▲ +13.0% QoQ | V12: ▲ +32.3% QoQ
B13: Target: $190K | D13: Q4 2024 | F13: Min: 1.25x | H13: Q4 2024 | J13: Target: 95% | L13: Q4 2024 | N13: vs Budget +4.8% | P13: Q4 2024 | R13: Budget: $280K | T13: Q4 2024 | V13: Margin: 18.0% | X13: Q4 2024
A16: ▌ PERFORMANCE GAUGES
B18: NET OPERATING INCOME — Q4 2024 | D18: Projected YE | F18: DEBT SVC COVERAGE — Q4 2024 | H18: Projected YE | J18: PORTFOLIO OCCUPANCY — Q4 2024 | L18: Projected YE | N18: OPERATING CASH FLOW — Q4 2024 | P18: Projected YE | R18: GROSS REVENUE — Q4 2024 | T18: Projected YE | V18: NET INCOME — Q4 2024 | X18: Projected YE
B19: (YEAR-END GOAL) | F19: (Target: 1.25) | J19: (Target: 95%) | N19: vs Budget +4.8% | R19: Budget: $280K | V19: Margin: 18.0%
B20: =TEXT('⚙️ NOI Engine'!J18/1000,"$#,##0K") -> $180K | F20: =TEXT(IF('⚙️ NOI Engine'!J19<0,'⚙️ NOI Engine'!J18/ABS('⚙️ NOI Engine'!J19),0),"0.00x") -> 1.19x | J20: =TEXT('🏢 Property Metrics'!D12,"0.0%") -> 96.1% | N20: =TEXT('💵 Operating Cash Flow'!F14,"$#,##0K") -> $162K | R20: =TEXT('⚙️ NOI Engine'!J6/1000,"$#,##0K") -> $297K | V20: =TEXT('💵 Operating Cash Flow'!F6,"$#,##0K") -> $138K
B22: Poor | C22: Average | D22: Good | F22: Poor | G22: Average | H22: Good | J22: Poor | K22: Average | L22: Good | N22: Poor | O22: Average | P22: Good | R22: Poor | S22: Average | T22: Good | V22: Poor | W22: Average | X22: Good
B23: ="ACTUAL: "&TEXT('⚙️ NOI Engine'!J18/1000,"$#,##0K") -> ACTUAL: $180K | F23: ="ACTUAL: "&TEXT(IF('⚙️ NOI Engine'!J19<0,'⚙️ NOI Engine'!J18/ABS('⚙️ NOI Engine'!J19),0),"0.00") -> ACTUAL: 1.19 | J23: ="ACTUAL: "&TEXT('🏢 Property Metrics'!D12,"0.0%") -> ACTUAL: 96.1% | N23: ="ACTUAL: $"&TEXT('💵 Operating Cash Flow'!F14,"#,##0K") -> ACTUAL: $162K | R23: ="ACTUAL: $"&TEXT('⚙️ NOI Engine'!J6/1000,"#,##0K") -> ACTUAL: $297K | V23: ="ACTUAL: $"&TEXT('💵 Operating Cash Flow'!F6,"#,##0K") -> ACTUAL: $138K
B25: 0K | C25: 100K | D25: 200K | F25: 0x | G25: 1.0x | H25: 2.0x | J25: 0% | K25: 50% | L25: 100% | N25: 0K | O25: 100K | P25: 200K | R25: 0K | S25: 175K | T25: 350K | V25: 0K | W25: 100K | X25: 200K
B27: STATUS | C27: COMPLETION | D27: TARGET GAP | F27: STATUS | G27: COMPLETION | H27: TARGET GAP | J27: STATUS | K27: COMPLETION | L27: TARGET GAP | N27: STATUS | O27: COMPLETION | P27: TARGET GAP | R27: STATUS | S27: COMPLETION | T27: TARGET GAP | V27: STATUS | W27: COMPLETION | X27: TARGET GAP
B28: ON TRACK | C28: =TEXT('⚙️ NOI Engine'!J18/190000,"0%") -> 95% | D28: =TEXT(('⚙️ NOI Engine'!J18-190000)/190000,"+0%;-0%") -> -5% | F28: ON TRACK | G28: =TEXT(IF('⚙️ NOI Engine'!J19<0,'⚙️ NOI Engine'!J18/ABS('⚙️ NOI Engine'!J19),0)/1.25,"0%") -> 95% | H28: =TEXT((IF('⚙️ NOI Engine'!J19<0,'⚙️ NOI Engine'!J18/ABS('⚙️ NOI Engine'!J19),0)-1.25)/1.25,"+0%;-0%") -> -5% | J28: STRONG | K28: =TEXT('🏢 Property Metrics'!D12/0.95,"0%") -> 101% | L28: =TEXT(('🏢 Property Metrics'!D12-0.95)/0.95,"+0%;-0%") -> +1% | N28: ON TRACK | O28: =TEXT('💵 Operating Cash Flow'!F14/154,"0%") -> 105% | P28: =TEXT(('💵 Operating Cash Flow'!F14-154)/154,"+0%;-0%") -> +5% | R28: STRONG | S28: =TEXT('⚙️ NOI Engine'!J6/1000/280,"0%") -> 106% | T28: =TEXT(('⚙️ NOI Engine'!J6/1000-280)/280,"+0%;-0%") -> +6% | V28: ON TRACK | W28: =TEXT('💵 Operating Cash Flow'!F6/160,"0%") -> 86% | X28: =TEXT(('💵 Operating Cash Flow'!F6-160)/160,"+0%;-0%") -> -14%
C31: Jan | D31: Feb | E31: Mar | G31: Apr | H31: May | I31: Jun | K31: Jul | L31: Aug | M31: Sep | O31: Oct | P31: Nov | Q31: Dec | S31: TOTAL | Y31: Series | Z31: Total ($K)
A32: Actual | C32: ='🔢 Data Engine'!B2 -> 285 | D32: ='🔢 Data Engine'!B3 -> 310 | E32: ='🔢 Data Engine'!B4 -> 298 | G32: ='🔢 Data Engine'!B5 -> 340 | H32: ='🔢 Data Engine'!B6 -> 365 | I32: ='🔢 Data Engine'!B7 -> 380 | K32: ='🔢 Data Engine'!B8 -> 355 | L32: ='🔢 Data Engine'!B9 -> 420 | M32: ='🔢 Data Engine'!B10 -> 445 | O32: ='🔢 Data Engine'!B11 -> 470 | P32: ='🔢 Data Engine'!B12 -> 510 | Q32: ='🔢 Data Engine'!B13 -> 580 | S32: =C32+D32+E32+G32+H32+I32+K32+L32+M32+O32+P32+Q32 -> 4758 | Y32: Actual | Z32: =S32 -> 4758
A33: Budget | C33: ='🔢 Data Engine'!C2 -> 300 | D33: ='🔢 Data Engine'!C3 -> 320 | E33: ='🔢 Data Engine'!C4 -> 310 | G33: ='🔢 Data Engine'!C5 -> 350 | H33: ='🔢 Data Engine'!C6 -> 370 | I33: ='🔢 Data Engine'!C7 -> 390 | K33: ='🔢 Data Engine'!C8 -> 370 | L33: ='🔢 Data Engine'!C9 -> 410 | M33: ='🔢 Data Engine'!C10 -> 440 | O33: ='🔢 Data Engine'!C11 -> 460 | P33: ='🔢 Data Engine'!C12 -> 500 | Q33: ='🔢 Data Engine'!C13 -> 560 | S33: =C33+D33+E33+G33+H33+I33+K33+L33+M33+O33+P33+Q33 -> 4780 | Y33: Budget | Z33: =S33 -> 4780
A34: Var $ | C34: =C32-C33 -> -15 | D34: =D32-D33 -> -10 | E34: =E32-E33 -> -12 | G34: =G32-G33 -> -10 | H34: =H32-H33 -> -5 | I34: =I32-I33 -> -10 | K34: =K32-K33 -> -15 | L34: =L32-L33 -> 10 | M34: =M32-M33 -> 5 | O34: =O32-O33 -> 10 | P34: =P32-P33 -> 10 | Q34: =Q32-Q33 -> 20 | S34: =C34+D34+E34+G34+H34+I34+K34+L34+M34+O34+P34+Q34 -> -22
A38: ▌ PROPERTY PERFORMANCE SNAPSHOT — ALL ASSETS | Q4 2024
A43: PROPERTY | D43: OCCUPANCY | G43: NOI | I43: DSCR | L43: GROSS RENT | O43: CASH FLOW | Q43: CAP RATE | T43: STATUS
A44: ='📥 Data Pulls'!B28 -> Jan-24 | D44: =TEXT('📥 Data Pulls'!C28,"0%") -> 2500000% | G44: =TEXT('📥 Data Pulls'!D28/1000,"$#,##0K") -> $1K | I44: =TEXT('📥 Data Pulls'!E28,"0.00x") -> 24000.00x | L44: =TEXT('📥 Data Pulls'!F28/1000,"$#,##0K") -> $9K | O44: =TEXT('📥 Data Pulls'!G28/1000,"$#,##0K") -> $15K | Q44: =TEXT('📥 Data Pulls'!H28,"0.0%") -> 1266700.0% | T44: ✅ Stable
A45: ='📥 Data Pulls'!B29 -> Feb-24 | D45: =TEXT('📥 Data Pulls'!C29,"0%") -> 2500000% | G45: =TEXT('📥 Data Pulls'!D29/1000,"$#,##0K") -> $1K | I45: =TEXT('📥 Data Pulls'!E29,"0.00x") -> 24000.00x | L45: =TEXT('📥 Data Pulls'!F29/1000,"$#,##0K") -> $9K | O45: =TEXT('📥 Data Pulls'!G29/1000,"$#,##0K") -> $15K | Q45: =TEXT('📥 Data Pulls'!H29,"0.0%") -> 1266700.0% | T45: ✅ Strong
A46: ='📥 Data Pulls'!B30 -> Mar-24 | D46: =TEXT('📥 Data Pulls'!C30,"0%") -> 2500000% | G46: =TEXT('📥 Data Pulls'!D30/1000,"$#,##0K") -> $1K | I46: =TEXT('📥 Data Pulls'!E30,"0.00x") -> 24000.00x | L46: =TEXT('📥 Data Pulls'!F30/1000,"$#,##0K") -> $9K | O46: =TEXT('📥 Data Pulls'!G30/1000,"$#,##0K") -> $15K | Q46: =TEXT('📥 Data Pulls'!H30,"0.0%") -> 1266700.0% | T46: ⚠️ Watch
A47: ='📥 Data Pulls'!B31 -> Apr-24 | D47: =TEXT('📥 Data Pulls'!C31,"0%") -> 2500000% | G47: =TEXT('📥 Data Pulls'!D31/1000,"$#,##0K") -> $1K | I47: =TEXT('📥 Data Pulls'!E31,"0.00x") -> 24000.00x | L47: =TEXT('📥 Data Pulls'!F31/1000,"$#,##0K") -> $9K | O47: =TEXT('📥 Data Pulls'!G31/1000,"$#,##0K") -> $15K | Q47: =TEXT('📥 Data Pulls'!H31,"0.0%") -> 1266700.0% | T47: ✅ Strong
A48: ='📥 Data Pulls'!B32 -> May-24 | D48: =TEXT('📥 Data Pulls'!C32,"0%") -> 2500000% | G48: =TEXT('📥 Data Pulls'!D32/1000,"$#,##0K") -> $1K | I48: =TEXT('📥 Data Pulls'!E32,"0.00x") -> 24000.00x | L48: =TEXT('📥 Data Pulls'!F32/1000,"$#,##0K") -> $9K | O48: =TEXT('📥 Data Pulls'!G32/1000,"$#,##0K") -> $15K | Q48: =TEXT('📥 Data Pulls'!H32,"0.0%") -> 1266700.0% | T48: ✅ Stable
A49: PORTFOLIO TOTAL / AVG | D49: =TEXT(AVERAGE('📥 Data Pulls'!C28:C32),"0.0%") -> 2500000.0% | G49: $169.2K | I49: 1.40x avg | L49: $295.0K | O49: $62.7K | Q49: 6.7% avg | T49: ✅ HEALTHY
V57: Property | W57: Occupancy (%) | X57: NOI ($K) | Y57: Cash Flow ($K)
V58: The Meridian | W58: 94 | X58: 23.7 | Y58: 8.2
V59: Parkview Plaza | W59: 98 | X59: 40 | Y59: 15
V60: Oakwood Lofts | W60: 88 | X60: 18.5 | Y60: 5.5
V61: Summit Towers | W61: 100 | X61: 57 | Y61: 24
V62: River's Edge | W62: 91 | X62: 30 | Y62: 10

Sheet 📊 DSCR Compliance
B2: 📊 DSCR COVENANT COMPLIANCE MONITOR
B3: Debt Service Coverage Ratio | Month-by-Month Compliance Tracking | Required DSCR Input → Cell H7
B5: ANNUALIZED NOI | D5: ANNUAL DEBT SVC | F5: PORTFOLIO DSCR | H5: REQUIRED DSCR ⬅ INPUT | J5: PORTFOLIO STATUS
B6: =SUM('📥 Data Pulls'!G13:G24) -> 180249.6 | D6: =SUM('📥 Data Pulls'!H13:H24) -> 152004 | F6: =IF(E6>0,B6/E6,0) -> 0 | H6: 1.25 | J6: =IF(F6>=H6,"✅ COMPLIANT",IF(F6>=H6*0.9,"⚠️ AT RISK","🚨 CRITICAL")) -> 🚨 CRITICAL
B10: ▌ MONTH-BY-MONTH DSCR COMPLIANCE TRACKER
B11: MONTH | C11: MONTHLY NOI | D11: ANNLZD NOI | E11: MONTHLY DS | F11: DSCR (ANN.) | G11: REQUIRED | H11: HEADROOM | I11: STATUS | J11: TREND | K11: COVENANT NOTE
B12: Jan-24 | C12: ='📥 Data Pulls'!G13 -> 14821.12 | D12: =C12*12 -> 177853.44 | E12: ='📥 Data Pulls'!H13 -> 12667 | F12: =IF(E12*12>0,D12/(E12*12),0) -> 1.1700576 | G12: =$H$6 -> 1.25 | H12: =F12-G12 -> -0.07994237 | I12: =IF(F12>=$H$6,"✅ COMPLIANT",IF(F12>=$H$6*0.9,"⚠️ AT RISK","🚨 CRITICAL")) -> ⚠️ AT RISK | J12: — | K12: =IF(F12<$H$6*0.9,"⚠ BREACH RISK — NOTIFY LENDER",IF(F12<$H$6,"Monitor Closely","In Compliance")) -> Monitor Closely
B13: Feb-24 | C13: ='📥 Data Pulls'!G14 -> 14272 | D13: =C13*12 -> 171264 | E13: ='📥 Data Pulls'!H14 -> 12667 | F13: =IF(E13*12>0,D13/(E13*12),0) -> 1.1267072 | G13: =$H$6 -> 1.25 | H13: =F13-G13 -> -0.12329281 | I13: =IF(F13>=$H$6,"✅ COMPLIANT",IF(F13>=$H$6*0.9,"⚠️ AT RISK","🚨 CRITICAL")) -> ⚠️ AT RISK | J13: =IF(F13>F12,"▲ IMPROVING",IF(F13<F12,"▼ DECLINING","→ STABLE")) -> ▼ DECLINING | K13: =IF(F13<$H$6*0.9,"⚠ BREACH RISK — NOTIFY LENDER",IF(F13<$H$6,"Monitor Closely","In Compliance")) -> Monitor Closely
B14: Mar-24 | C14: ='📥 Data Pulls'!G15 -> 14821.12 | D14: =C14*12 -> 177853.44 | E14: ='📥 Data Pulls'!H15 -> 12667 | F14: =IF(E14*12>0,D14/(E14*12),0) -> 1.1700576 | G14: =$H$6 -> 1.25 | H14: =F14-G14 -> -0.07994237 | I14: =IF(F14>=$H$6,"✅ COMPLIANT",IF(F14>=$H$6*0.9,"⚠️ AT RISK","🚨 CRITICAL")) -> ⚠️ AT RISK | J14: =IF(F14>F13,"▲ IMPROVING",IF(F14<F13,"▼ DECLINING","→ STABLE")) -> ▲ IMPROVING | K14: =IF(F14<$H$6*0.9,"⚠ BREACH RISK — NOTIFY LENDER",IF(F14<$H$6,"Monitor Closely","In Compliance")) -> Monitor Closely
B15: Apr-24 | C15: ='📥 Data Pulls'!G16 -> 14821.12 | D15: =C15*12 -> 177853.44 | E15: ='📥 Data Pulls'!H16 -> 12667 | F15: =IF(E15*12>0,D15/(E15*12),0) -> 1.1700576 | G15: =$H$6 -> 1.25 | H15: =F15-G15 -> -0.07994237 | I15: =IF(F15>=$H$6,"✅ COMPLIANT",IF(F15>=$H$6*0.9,"⚠️ AT RISK","🚨 CRITICAL")) -> ⚠️ AT RISK | J15: =IF(F15>F14,"▲ IMPROVING",IF(F15<F14,"▼ DECLINING","→ STABLE")) -> → STABLE | K15: =IF(F15<$H$6*0.9,"⚠ BREACH RISK — NOTIFY LENDER",IF(F15<$H$6,"Monitor Closely","In Compliance")) -> Monitor Closely
B16: May-24 | C16: ='📥 Data Pulls'!G17 -> 15168 | D16: =C16*12 -> 182016 | E16: ='📥 Data Pulls'!H17 -> 12667 | F16: =IF(E16*12>0,D16/(E16*12),0) -> 1.1974422 | G16: =$H$6 -> 1.25 | H16: =F16-G16 -> -0.052557827 | I16: =IF(F16>=$H$6,"✅ COMPLIANT",IF(F16>=$H$6*0.9,"⚠️ AT RISK","🚨 CRITICAL")) -> ⚠️ AT RISK | J16: =IF(F16>F15,"▲ IMPROVING",IF(F16<F15,"▼ DECLINING","→ STABLE")) -> ▲ IMPROVING | K16: =IF(F16<$H$6*0.9,"⚠ BREACH RISK — NOTIFY LENDER",IF(F16<$H$6,"Monitor Closely","In Compliance")) -> Monitor Closely
B17: Jun-24 | C17: ='📥 Data Pulls'!G18 -> 15488 | D17: =C17*12 -> 185856 | E17: ='📥 Data Pulls'!H18 -> 12667 | F17: =IF(E17*12>0,D17/(E17*12),0) -> 1.2227047 | G17: =$H$6 -> 1.25 | H17: =F17-G17 -> -0.027295334 | I17: =IF(F17>=$H$6,"✅ COMPLIANT",IF(F17>=$H$6*0.9,"⚠️ AT RISK","🚨 CRITICAL")) -> ⚠️ AT RISK | J17: =IF(F17>F16,"▲ IMPROVING",IF(F17<F16,"▼ DECLINING","→ STABLE")) -> ▲ IMPROVING | K17: =IF(F17<$H$6*0.9,"⚠ BREACH RISK — NOTIFY LENDER",IF(F17<$H$6,"Monitor Closely","In Compliance")) -> Monitor Closely
B18: Jul-24 | C18: ='📥 Data Pulls'!G19 -> 15488 | D18: =C18*12 -> 185856 | E18: ='📥 Data Pulls'!H19 -> 12667 | F18: =IF(E18*12>0,D18/(E18*12),0) -> 1.2227047 | G18: =$H$6 -> 1.25 | H18: =F18-G18 -> -0.027295334 | I18: =IF(F18>=$H$6,"✅ COMPLIANT",IF(F18>=$H$6*0.9,"⚠️ AT RISK","🚨 CRITICAL")) -> ⚠️ AT RISK | J18: =IF(F18>F17,"▲ IMPROVING",IF(F18<F17,"▼ DECLINING","→ STABLE")) -> → STABLE | K18: =IF(F18<$H$6*0.9,"⚠ BREACH RISK — NOTIFY LENDER",IF(F18<$H$6,"Monitor Closely","In Compliance")) -> Monitor Closely
B19: Aug-24 | C19: ='📥 Data Pulls'!G20 -> 15488 | D19: =C19*12 -> 185856 | E19: ='📥 Data Pulls'!H20 -> 12667 | F19: =IF(E19*12>0,D19/(E19*12),0) -> 1.2227047 | G19: =$H$6 -> 1.25 | H19: =F19-G19 -> -0.027295334 | I19: =IF(F19>=$H$6,"✅ COMPLIANT",IF(F19>=$H$6*0.9,"⚠️ AT RISK","🚨 CRITICAL")) -> ⚠️ AT RISK | J19: =IF(F19>F18,"▲ IMPROVING",IF(F19<F18,"▼ DECLINING","→ STABLE")) -> → STABLE | K19: =IF(F19<$H$6*0.9,"⚠ BREACH RISK — NOTIFY LENDER",IF(F19<$H$6,"Monitor Closely","In Compliance")) -> Monitor Closely
B20: Sep-24 | C20: ='📥 Data Pulls'!G21 -> 15200 | D20: =C20*12 -> 182400 | E20: ='📥 Data Pulls'!H21 -> 12667 | F20: =IF(E20*12>0,D20/(E20*12),0) -> 1.1999684 | G20: =$H$6 -> 1.25 | H20: =F20-G20 -> -0.050031578 | I20: =IF(F20>=$H$6,"✅ COMPLIANT",IF(F20>=$H$6*0.9,"⚠️ AT RISK","🚨 CRITICAL")) -> ⚠️ AT RISK | J20: =IF(F20>F19,"▲ IMPROVING",IF(F20<F19,"▼ DECLINING","→ STABLE")) -> ▼ DECLINING | K20: =IF(F20<$H$6*0.9,"⚠ BREACH RISK — NOTIFY LENDER",IF(F20<$H$6,"Monitor Closely","In Compliance")) -> Monitor Closely
B21: Oct-24 | C21: ='📥 Data Pulls'!G22 -> 15040 | D21: =C21*12 -> 180480 | E21: ='📥 Data Pulls'!H22 -> 12667 | F21: =IF(E21*12>0,D21/(E21*12),0) -> 1.1873372 | G21: =$H$6 -> 1.25 | H21: =F21-G21 -> -0.062662825 | I21: =IF(F21>=$H$6,"✅ COMPLIANT",IF(F21>=$H$6*0.9,"⚠️ AT RISK","🚨 CRITICAL")) -> ⚠️ AT RISK | J21: =IF(F21>F20,"▲ IMPROVING",IF(F21<F20,"▼ DECLINING","→ STABLE")) -> ▼ DECLINING | K21: =IF(F21<$H$6*0.9,"⚠ BREACH RISK — NOTIFY LENDER",IF(F21<$H$6,"Monitor Closely","In Compliance")) -> Monitor Closely
B22: Nov-24 | C22: ='📥 Data Pulls'!G23 -> 14821.12 | D22: =C22*12 -> 177853.44 | E22: ='📥 Data Pulls'!H23 -> 12667 | F22: =IF(E22*12>0,D22/(E22*12),0) -> 1.1700576 | G22: =$H$6 -> 1.25 | H22: =F22-G22 -> -0.07994237 | I22: =IF(F22>=$H$6,"✅ COMPLIANT",IF(F22>=$H$6*0.9,"⚠️ AT RISK","🚨 CRITICAL")) -> ⚠️ AT RISK | J22: =IF(F22>F21,"▲ IMPROVING",IF(F22<F21,"▼ DECLINING","→ STABLE")) -> ▼ DECLINING | K22: =IF(F22<$H$6*0.9,"⚠ BREACH RISK — NOTIFY LENDER",IF(F22<$H$6,"Monitor Closely","In Compliance")) -> Monitor Closely
B23: Dec-24 | C23: ='📥 Data Pulls'!G24 -> 14821.12 | D23: =C23*12 -> 177853.44 | E23: ='📥 Data Pulls'!H24 -> 12667 | F23: =IF(E23*12>0,D23/(E23*12),0) -> 1.1700576 | G23: =$H$6 -> 1.25 | H23: =F23-G23 -> -0.07994237 | I23: =IF(F23>=$H$6,"✅ COMPLIANT",IF(F23>=$H$6*0.9,"⚠️ AT RISK","🚨 CRITICAL")) -> ⚠️ AT RISK | J23: =IF(F23>F22,"▲ IMPROVING",IF(F23<F22,"▼ DECLINING","→ STABLE")) -> → STABLE | K23: =IF(F23<$H$6*0.9,"⚠ BREACH RISK — NOTIFY LENDER",IF(F23<$H$6,"Monitor Closely","In Compliance")) -> Monitor Closely
B24: FULL YEAR | C24: =SUM('📥 Data Pulls'!G13:G24) -> 180249.6 | D24: =C24 -> 180249.6 | E24: =SUM('📥 Data Pulls'!H13:H24) -> 152004 | F24: =IF(E24>0,C24/E24,0) -> 1.1858214 | G24: =$H$6 -> 1.25 | H24: =F24-G24 -> -0.064178574 | I24: =IF(F24>=$H$6,"✅ COMPLIANT",IF(F24>=$H$6*0.9,"⚠️ AT RISK","🚨 CRITICAL")) -> ⚠️ AT RISK | K24: ANNUAL COVENANT CHECK
B26: ⚙️ To change the required DSCR covenant threshold, edit cell H6 (currently 1.25x). All status cells and the compliance tracker will update automatically.

Sheet 🔢 Data Engine
A1: Month | B1: Revenue Actual ($K) | C1: Revenue Budget ($K) | D1: Net Income ($K) | E1: EBITDA ($K) | F1: Gross Profit ($K) | H1: Segment | I1: Revenue ($K) | K1: Property | L1: Total Units | M1: Rev Per Unit | N1: NOI ($K)
A2: Jan | B2: 285 | C2: 300 | D2: 48 | E2: 75 | F2: 160 | H2: Property Mgmt | I2: 2100 | K2: Property A | L2: ='🏢 Property Metrics'!L12 -> 332 | M2: ='⚙️ NOI Engine'!J6/'🏢 Property Metrics'!L12 -> 895.82831 | N2: 320
A3: Feb | B3: 310 | C3: 320 | D3: 55 | E3: 82 | F3: 174 | H3: Asset Advisory | I3: 1500 | K3: Property B | L3: 1.52 | M3: 98 | N3: 415
A4: Mar | B4: 298 | C4: 310 | D4: 52 | E4: 79 | F4: 167 | H4: CFO Services | I4: 1200 | K4: Property C | L4: 1.18 | M4: 88 | N4: 280
A5: Apr | B5: 340 | C5: 350 | D5: 68 | E5: 90 | F5: 191 | H5: Controller Svcs | I5: 600 | K5: Property D | L5: 1.67 | M5: 100 | N5: 510
A6: May | B6: 365 | C6: 370 | D6: 74 | E6: 97 | F6: 205 | H6: Other | I6: 400 | K6: Property E | L6: 1.29 | M6: 91 | N6: 365
A7: Jun | B7: 380 | C7: 390 | D7: 80 | E7: 101 | F7: 213
A8: Jul | B8: 355 | C8: 370 | D8: 71 | E8: 94 | F8: 199
A9: Aug | B9: 420 | C9: 410 | D9: 92 | E9: 111 | F9: 236
A10: Sep | B10: 445 | C10: 440 | D10: 98 | E10: 118 | F10: 250
A11: Oct | B11: 470 | C11: 460 | D11: 105 | E11: 125 | F11: 264
A12: Nov | B12: 510 | C12: 500 | D12: 118 | E12: 135 | F12: 286
A13: Dec | B13: 580 | C13: 560 | D13: 138 | E13: 154 | F13: 325

Sheet 🏢 Property Metrics
B4: ▌ PROPERTY PERFORMANCE MATRIX
B6: PROPERTY | C6: DSCR | D6: OCCUPANCY % | E6: GROSS RENT | F6: VACANCY LOSS | G6: EFF. GROSS INC | H6: OP. EXPENSES | I6: NOI | J6: CAP RATE | K6: CASH FLOW | L6: UNITS | M6: REV/UNIT | N6: OCCUPIED UNITS
B7: The Meridian | C7: 1.35 | D7: =IFERROR(N7/L7,0) -> 0.9375 | E7: 42000 | F7: =-(L7-N7)*(E7/L7) -> -2625 | G7: =E7+F7 -> 39375 | H7: =-G7*'📋 Assumptions'!C15 -> -14175 | I7: =G7+H7 -> 25200 | J7: 0.062 | K7: =IFERROR(I7-I7/C7,0) -> 6533.3333 | L7: 48 | M7: =E7/L7 -> 875 | N7: 45
B8: Parkview Plaza | C8: 1.52 | D8: =IFERROR(N8/L8,0) -> 0.98611111 | E8: 68000 | F8: =-(L8-N8)*(E8/L8) -> -944.44444 | G8: =E8+F8 -> 67055.556 | H8: =-G8*'📋 Assumptions'!C15 -> -24140 | I8: =G8+H8 -> 42915.556 | J8: 0.071 | K8: =IFERROR(I8-I8/C8,0) -> 14681.637 | L8: 72 | M8: =E8/L8 -> 944.44444 | N8: 71
B9: Oakwood Lofts | C9: 1.18 | D9: =IFERROR(N9/L9,0) -> 0.875 | E9: 35000 | F9: =-(L9-N9)*(E9/L9) -> -4375 | G9: =E9+F9 -> 30625 | H9: =-G9*'📋 Assumptions'!C15 -> -11025 | I9: =G9+H9 -> 19600 | J9: 0.058 | K9: =IFERROR(I9-I9/C9,0) -> 2989.8305 | L9: 32 | M9: =E9/L9 -> 1093.75 | N9: 28
B10: Summit Towers | C10: 1.67 | D10: =IFERROR(N10/L10,0) -> 1 | E10: 95000 | F10: =-(L10-N10)*(E10/L10) -> 0 | G10: =E10+F10 -> 95000 | H10: =-G10*'📋 Assumptions'!C15 -> -34200 | I10: =G10+H10 -> 60800 | J10: 0.078 | K10: =IFERROR(I10-I10/C10,0) -> 24392.814 | L10: 120 | M10: =E10/L10 -> 791.66667 | N10: 120
B11: River's Edge | C11: 1.29 | D11: =IFERROR(N11/L11,0) -> 0.91666667 | E11: 55000 | F11: =-(L11-N11)*(E11/L11) -> -4583.3333 | G11: =E11+F11 -> 50416.667 | H11: =-G11*'📋 Assumptions'!C15 -> -18150 | I11: =G11+H11 -> 32266.667 | J11: 0.065 | K11: =IFERROR(I11-I11/C11,0) -> 7253.7468 | L11: 60 | M11: =E11/L11 -> 916.66667 | N11: 55
B12: PORTFOLIO TOTAL | C12: =AVERAGE(C7:C11) -> 1.402 | D12: =IFERROR(SUM(N7:N11)/SUM(L7:L11),0) -> 0.96084337 | E12: =SUM(E7:E11) -> 295000 | F12: =SUM(F7:F11) -> -12527.778 | G12: =SUM(G7:G11) -> 282472.22 | H12: =SUM(H7:H11) -> -101690 | I12: =SUM(I7:I11) -> 180782.22 | J12: =AVERAGE(J7:J11) -> 0.0668 | K12: =SUM(K7:K11) -> 55851.362 | L12: =SUM(L7:L11) -> 332 | M12: =E12/L12 -> 888.55422 | N12: =SUM(N7:N11) -> 319
B14: ▌ DSCR GAUGE — MINIMUM THRESHOLD: 1.25x
B16: The Meridian | D16: 1.35x | E16: ██████░░░░ | L16: ✅ PASS
B18: Parkview Plaza | D18: 1.52x | E18: ███████░░░ | L18: ✅ PASS
B20: Oakwood Lofts | D20: 1.18x | E20: █████░░░░░ | L20: ❌ FAIL
B22: Summit Towers | D22: 1.67x | E22: ████████░░ | L22: ✅ PASS
B24: River's Edge | D24: 1.29x | E24: ██████░░░░ | L24: ✅ PASS
B27: ▌ PORTFOLIO MONTHLY PERFORMANCE — ACTUAL DATA INPUT
B28: MONTH | C28: GROSS RENT | D28: VACANCY | E28: EGI | F28: OP EXP | G28: NOI | H28: DEBT SVC | I28: CASH FLOW | J28: OCCUPANCY | K28: DSCR
B29: Jan-24 | C29: ='📥 Data Pulls'!C13 -> 24583 | D29: ='📥 Data Pulls'!D13 -> 1425 | E29: ='📥 Data Pulls'!E13 -> 23158 | F29: ='📥 Data Pulls'!F13 -> 8336.88 | G29: ='📥 Data Pulls'!G13 -> 14821.12 | H29: ='📥 Data Pulls'!H13 -> 12667 | I29: ='📥 Data Pulls'!I13 -> 2154.12 | J29: ='📥 Data Pulls'!J13 -> 0.94203311 | K29: ='📥 Data Pulls'!K13 -> 1.1700576
B30: Feb-24 | C30: ='📥 Data Pulls'!C14 -> 24100 | D30: ='📥 Data Pulls'!D14 -> 1800 | E30: ='📥 Data Pulls'!E14 -> 22300 | F30: ='📥 Data Pulls'!F14 -> 8028 | G30: ='📥 Data Pulls'!G14 -> 14272 | H30: ='📥 Data Pulls'!H14 -> 12667 | I30: ='📥 Data Pulls'!I14 -> 1605 | J30: ='📥 Data Pulls'!J14 -> 0.9253112 | K30: ='📥 Data Pulls'!K14 -> 1.1267072
B31: Mar-24 | C31: ='📥 Data Pulls'!C15 -> 24583 | D31: ='📥 Data Pulls'!D15 -> 1425 | E31: ='📥 Data Pulls'!E15 -> 23158 | F31: ='📥 Data Pulls'!F15 -> 8336.88 | G31: ='📥 Data Pulls'!G15 -> 14821.12 | H31: ='📥 Data Pulls'!H15 -> 12667 | I31: ='📥 Data Pulls'!I15 -> 2154.12 | J31: ='📥 Data Pulls'!J15 -> 0.94203311 | K31: ='📥 Data Pulls'!K15 -> 1.1700576
B32: Apr-24 | C32: ='📥 Data Pulls'!C16 -> 24583 | D32: ='📥 Data Pulls'!D16 -> 1425 | E32: ='📥 Data Pulls'!E16 -> 23158 | F32: ='📥 Data Pulls'!F16 -> 8336.88 | G32: ='📥 Data Pulls'!G16 -> 14821.12 | H32: ='📥 Data Pulls'!H16 -> 12667 | I32: ='📥 Data Pulls'!I16 -> 2154.12 | J32: ='📥 Data Pulls'!J16 -> 0.94203311 | K32: ='📥 Data Pulls'!K16 -> 1.1700576
B33: May-24 | C33: ='📥 Data Pulls'!C17 -> 24900 | D33: ='📥 Data Pulls'!D17 -> 1200 | E33: ='📥 Data Pulls'!E17 -> 23700 | F33: ='📥 Data Pulls'!F17 -> 8532 | G33: ='📥 Data Pulls'!G17 -> 15168 | H33: ='📥 Data Pulls'!H17 -> 12667 | I33: ='📥 Data Pulls'!I17 -> 2501 | J33: ='📥 Data Pulls'!J17 -> 0.95180723 | K33: ='📥 Data Pulls'!K17 -> 1.1974422
B34: Jun-24 | C34: ='📥 Data Pulls'!C18 -> 25200 | D34: ='📥 Data Pulls'!D18 -> 1000 | E34: ='📥 Data Pulls'!E18 -> 24200 | F34: ='📥 Data Pulls'!F18 -> 8712 | G34: ='📥 Data Pulls'!G18 -> 15488 | H34: ='📥 Data Pulls'!H18 -> 12667 | I34: ='📥 Data Pulls'!I18 -> 2821 | J34: ='📥 Data Pulls'!J18 -> 0.96031746 | K34: ='📥 Data Pulls'!K18 -> 1.2227047
B35: Jul-24 | C35: ='📥 Data Pulls'!C19 -> 25200 | D35: ='📥 Data Pulls'!D19 -> 1000 | E35: ='📥 Data Pulls'!E19 -> 24200 | F35: ='📥 Data Pulls'!F19 -> 8712 | G35: ='📥 Data Pulls'!G19 -> 15488 | H35: ='📥 Data Pulls'!H19 -> 12667 | I35: ='📥 Data Pulls'!I19 -> 2821 | J35: ='📥 Data Pulls'!J19 -> 0.96031746 | K35: ='📥 Data Pulls'!K19 -> 1.2227047
B36: Aug-24 | C36: ='📥 Data Pulls'!C20 -> 25200 | D36: ='📥 Data Pulls'!D20 -> 1000 | E36: ='📥 Data Pulls'!E20 -> 24200 | F36: ='📥 Data Pulls'!F20 -> 8712 | G36: ='📥 Data Pulls'!G20 -> 15488 | H36: ='📥 Data Pulls'!H20 -> 12667 | I36: ='📥 Data Pulls'!I20 -> 2821 | J36: ='📥 Data Pulls'!J20 -> 0.96031746 | K36: ='📥 Data Pulls'!K20 -> 1.2227047
B37: Sep-24 | C37: ='📥 Data Pulls'!C21 -> 25000 | D37: ='📥 Data Pulls'!D21 -> 1250 | E37: ='📥 Data Pulls'!E21 -> 23750 | F37: ='📥 Data Pulls'!F21 -> 8550 | G37: ='📥 Data Pulls'!G21 -> 15200 | H37: ='📥 Data Pulls'!H21 -> 12667 | I37: ='📥 Data Pulls'!I21 -> 2533 | J37: ='📥 Data Pulls'!J21 -> 0.95 | K37: ='📥 Data Pulls'!K21 -> 1.1999684
B38: Oct-24 | C38: ='📥 Data Pulls'!C22 -> 24900 | D38: ='📥 Data Pulls'!D22 -> 1400 | E38: ='📥 Data Pulls'!E22 -> 23500 | F38: ='📥 Data Pulls'!F22 -> 8460 | G38: ='📥 Data Pulls'!G22 -> 15040 | H38: ='📥 Data Pulls'!H22 -> 12667 | I38: ='📥 Data Pulls'!I22 -> 2373 | J38: ='📥 Data Pulls'!J22 -> 0.9437751 | K38: ='📥 Data Pulls'!K22 -> 1.1873372
B39: Nov-24 | C39: ='📥 Data Pulls'!C23 -> 24583 | D39: ='📥 Data Pulls'!D23 -> 1425 | E39: ='📥 Data Pulls'!E23 -> 23158 | F39: ='📥 Data Pulls'!F23 -> 8336.88 | G39: ='📥 Data Pulls'!G23 -> 14821.12 | H39: ='📥 Data Pulls'!H23 -> 12667 | I39: ='📥 Data Pulls'!I23 -> 2154.12 | J39: ='📥 Data Pulls'!J23 -> 0.94203311 | K39: ='📥 Data Pulls'!K23 -> 1.1700576
B40: Dec-24 | C40: ='📥 Data Pulls'!C24 -> 24583 | D40: ='📥 Data Pulls'!D24 -> 1425 | E40: ='📥 Data Pulls'!E24 -> 23158 | F40: ='📥 Data Pulls'!F24 -> 8336.88 | G40: ='📥 Data Pulls'!G24 -> 14821.12 | H40: ='📥 Data Pulls'!H24 -> 12667 | I40: ='📥 Data Pulls'!I24 -> 2154.12 | J40: ='📥 Data Pulls'!J24 -> 0.94203311 | K40: ='📥 Data Pulls'!K24 -> 1.1700576

Sheet ⚙️ NOI Engine
B4: ▌ NOI WATERFALL — CONSOLIDATED
B6: GROSS POTENTIAL RENT | J6: =SUM('📥 Data Pulls'!C13:C24) -> 297415
B7: Vacancy Loss | J7: =-SUM('📥 Data Pulls'!D13:D24) -> -15775
B8: Concessions | J8: =-'📋 Assumptions'!C38 -> -2950
B9: Credit Loss | J9: =-SUM('📥 Data Pulls'!E13:E24)*'📋 Assumptions'!C10 -> -1408.2
B10: EFFECTIVE GROSS INCOME | J10: =SUM('📥 Data Pulls'!E13:E24) -> 281640
B11: Management Fees | J11: =-SUM('📥 Data Pulls'!E13:E24)*'📋 Assumptions'!C16 -> -14082
B12: Insurance | J12: =-'📋 Assumptions'!C41 -> -8275
B13: Property Taxes | J13: =-'📋 Assumptions'!C42 -> -22066
B14: Maintenance & Repairs | J14: =-SUM('📥 Data Pulls'!E13:E24)*'📋 Assumptions'!C43 -> -22531.2
B15: Utilities | J15: =-SUM('📥 Data Pulls'!E13:E24)*'📋 Assumptions'!C44 -> -7041
B16: Administrative | J16: =-SUM('📥 Data Pulls'!E13:E24)*'📋 Assumptions'!C45 -> -5069.52
B17: TOTAL OPERATING EXPENSES | J17: =ABS(J11)+ABS(J12)+ABS(J13)+ABS(J14)+ABS(J15)+ABS(J16) -> 79064.72
B18: NET OPERATING INCOME | J18: =SUM('📥 Data Pulls'!G13:G24) -> 180249.6
B19: Debt Service (Annual) | J19: =-SUM('📥 Data Pulls'!H13:H24) -> -152004
B20: CASH FLOW AFTER DEBT | J20: =SUM('📥 Data Pulls'!I13:I24) -> 28245.6

Sheet 📡 Forecasting
B4: ▌ ASSUMPTIONS
B6: Revenue Growth Rate | F6: ='📋 Assumptions'!C7 -> 0.08
B7: Expense Growth Rate | F7: ='📋 Assumptions'!C36 -> 0.045
B8: Vacancy Rate | F8: ='📋 Assumptions'!C9 -> 0.05
B9: CapEx % of Revenue | F9: ='📋 Assumptions'!C37 -> 0.03
B10: Debt Service (Annual) | F10: ='💳 Amortization'!F11*12 -> 151696.33
B13: ▌ 5-YEAR FORECAST
B15: METRIC | C15: 2024A | D15: 2025E | E15: 2026E | F15: 2027E | G15: 2028E
B16: Gross Revenue | C16: =TEXT('⚙️ NOI Engine'!J6/1000,"$#,##0K") -> $297K | D16: ='⚙️ NOI Engine'!J6/1000*(1+'📋 Assumptions'!C7) -> 321.2082 | E16: =D16*(1+'📋 Assumptions'!C7) -> 346.90486 | F16: =E16*(1+'📋 Assumptions'!C7) -> 374.65724 | G16: =F16*(1+'📋 Assumptions'!C7) -> 404.62982
B17: Gross Profit | C17: $1,989K | D17: $2,152K | E17: $2,328K | F17: $2,516K | G17: $2,718K
B18: EBITDA | C18: $942K | D18: $1,027K | E18: $1,116K | F18: $1,213K | G18: $1,320K
B19: Net Income | C19: $601K | D19: $658K | E19: $720K | F19: $789K | G19: $867K
B20: NOI | C20: =TEXT('⚙️ NOI Engine'!J18/1000,"$#,##0K") -> $180K | D20: ='⚙️ NOI Engine'!J18/1000*(1+'📋 Assumptions'!C7) -> 194.66957 | E20: =D20*(1+'📋 Assumptions'!C7) -> 210.24313 | F20: =E20*(1+'📋 Assumptions'!C7) -> 227.06258 | G20: =F20*(1+'📋 Assumptions'!C7) -> 245.22759
B21: Cash Flow | C21: =TEXT('⚙️ NOI Engine'!J20/1000,"$#,##0K") -> $28K | D21: =D20-F10/1000 -> 42.973242 | E21: =E20-F10/1000 -> 58.546808 | F21: =F20-F10/1000 -> 75.366258 | G21: =G20-F10/1000 -> 93.531265
B22: DSCR | C22: =IFERROR('⚙️ NOI Engine'!J18/ABS('⚙️ NOI Engine'!J19),0) -> 1.1858214 | D22: =IFERROR(D20/(F10/1000),0) -> 1.2832847 | E22: =IFERROR(E20/(F10/1000),0) -> 1.3859474 | F22: =IFERROR(F20/(F10/1000),0) -> 1.4968232 | G22: =IFERROR(G20/(F10/1000),0) -> 1.6165691
B23: Occupancy | C23: ='🏢 Property Metrics'!D12 -> 0.96084337 | D23: =MIN(C23+0.008,1) -> 0.96884337 | E23: =MIN(D23+0.005,1) -> 0.97384337 | F23: =MIN(E23+0.005,1) -> 0.97884337 | G23: =MIN(F23+0.005,1) -> 0.98384337

Sheet 💳 Amortization
B4: ▌ LOAN PARAMETERS (BLUE CELLS = INPUT)
B6: Loan Amount | F6: ='📋 Assumptions'!C23 -> 2000000
B7: Annual Rate | F7: ='📋 Assumptions'!C24 -> 0.065
B8: Term (Years) | F8: ='📋 Assumptions'!C25 -> 30
B9: Start Date | F9: 45292
B11: Monthly Payment | F11: =PMT(F7/12,F8*12,-F6) -> 12641.36
B12: Total Interest Paid | F12: =F11*F8*12-F6 -> 2550889.8
B15: PERIOD | C15: DATE | D15: PAYMENT | E15: PRINCIPAL | F15: INTEREST | G15: BALANCE
B16: 1 | C16: =EDATE($F$9,B16-1) -> 45292 | D16: =$F$11 -> 12641.36 | E16: =D16-F16 -> 1808.0271 | F16: =F6*($F$7/12) -> 10833.333 | G16: =F6-E16 -> 1998192
B17: 2 | C17: =EDATE($F$9,B17-1) -> 45323 | D17: =$F$11 -> 12641.36 | E17: =D17-F17 -> 1817.8206 | F17: =G16*($F$7/12) -> 10823.54 | G17: =G16-E17 -> 1996374.2
B18: 3 | C18: =EDATE($F$9,B18-1) -> 45352 | D18: =$F$11 -> 12641.36 | E18: =D18-F18 -> 1827.6671 | F18: =G17*($F$7/12) -> 10813.693 | G18: =G17-E18 -> 1994546.5
B19: 4 | C19: =EDATE($F$9,B19-1) -> 45383 | D19: =$F$11 -> 12641.36 | E19: =D19-F19 -> 1837.567 | F19: =G18*($F$7/12) -> 10803.793 | G19: =G18-E19 -> 1992708.9
B20: 5 | C20: =EDATE($F$9,B20-1) -> 45413 | D20: =$F$11 -> 12641.36 | E20: =D20-F20 -> 1847.5205 | F20: =G19*($F$7/12) -> 10793.84 | G20: =G19-E20 -> 1990861.4
B21: 6 | C21: =EDATE($F$9,B21-1) -> 45444 | D21: =$F$11 -> 12641.36 | E21: =D21-F21 -> 1857.5279 | F21: =G20*($F$7/12) -> 10783.833 | G21: =G20-E21 -> 1989003.9
B22: 7 | C22: =EDATE($F$9,B22-1) -> 45474 | D22: =$F$11 -> 12641.36 | E22: =D22-F22 -> 1867.5895 | F22: =G21*($F$7/12) -> 10773.771 | G22: =G21-E22 -> 1987136.3
B23: 8 | C23: =EDATE($F$9,B23-1) -> 45505 | D23: =$F$11 -> 12641.36 | E23: =D23-F23 -> 1877.7056 | F23: =G22*($F$7/12) -> 10763.655 | G23: =G22-E23 -> 1985258.6
B24: 9 | C24: =EDATE($F$9,B24-1) -> 45536 | D24: =$F$11 -> 12641.36 | E24: =D24-F24 -> 1887.8765 | F24: =G23*($F$7/12) -> 10753.484 | G24: =G23-E24 -> 1983370.7
B25: 10 | C25: =EDATE($F$9,B25-1) -> 45566 | D25: =$F$11 -> 12641.36 | E25: =D25-F25 -> 1898.1025 | F25: =G24*($F$7/12) -> 10743.258 | G25: =G24-E25 -> 1981472.6
B26: 11 | C26: =EDATE($F$9,B26-1) -> 45597 | D26: =$F$11 -> 12641.36 | E26: =D26-F26 -> 1908.3839 | F26: =G25*($F$7/12) -> 10732.977 | G26: =G25-E26 -> 1979564.2
B27: 12 | C27: =EDATE($F$9,B27-1) -> 45627 | D27: =$F$11 -> 12641.36 | E27: =D27-F27 -> 1918.721 | F27: =G26*($F$7/12) -> 10722.639 | G27: =G26-E27 -> 1977645.5
B28: 13 | C28: =EDATE($F$9,B28-1) -> 45658 | D28: =$F$11 -> 12641.36 | E28: =D28-F28 -> 1929.1141 | F28: =G27*($F$7/12) -> 10712.246 | G28: =G27-E28 -> 1975716.4
... B75: 60 | C75: =EDATE($F$9,B75-1) -> 47088 | D75: =$F$11 -> 12641.36 | E75: =D75-F75 -> 2486.7016 | F75: =G74*($F$7/12) -> 10154.659 | G75: =G74-E75 -> 1872219.5

Sheet 🏗️ Capital Plan
B4: ▌ CAPITAL EXPENDITURE PLAN — ALL PROPERTIES
B6: CATEGORY | C6: 2024A | D6: 2025E | E6: 2026E | F6: 2027E | G6: 2028E | H6: TOTAL
B7: Roof Replacement | C7: 85000 | D7: 0 | E7: 120000 | F7: 0 | G7: 0 | H7: =SUM(C7:G7) -> 205000
B8: HVAC Systems | C8: 45000 | D8: 62000 | E8: 0 | F8: 78000 | G8: 0 | H8: =SUM(C8:G8) -> 185000
B9: Plumbing Upgrades | C9: 12000 | D9: 18000 | E9: 22000 | F9: 15000 | G9: 28000 | H9: =SUM(C9:G9) -> 95000
B10: Electrical Systems | C10: 32000 | D10: 0 | E10: 48000 | F10: 0 | G10: 55000 | H10: =SUM(C10:G10) -> 135000
B11: Parking Lot | C11: 0 | D11: 28000 | E11: 0 | F11: 0 | G11: 35000 | H11: =SUM(C11:G11) -> 63000
B12: Interior Renovations | C12: 55000 | D12: 72000 | E12: 88000 | F12: 95000 | G12: 102000 | H12: =SUM(C12:G12) -> 412000
B13: Landscaping | C13: 8000 | D13: 9500 | E13: 10000 | F13: 10500 | G13: 11000 | H13: =SUM(C13:G13) -> 49000
B14: Security Systems | C14: 22000 | D14: 5000 | E14: 5000 | F14: 5000 | G14: 28000 | H14: =SUM(C14:G14) -> 65000
B15: Energy Efficiency | C15: 38000 | D15: 42000 | E15: 45000 | F15: 48000 | G15: 52000 | H15: =SUM(C15:G15) -> 225000
B16: Contingency (10%) | C16: 29700 | D16: 23650 | E16: 33800 | F16: 25150 | G16: 31100 | H16: =SUM(C16:G16) -> 143400
B18: TOTAL CAPITAL EXPENDITURE | C18: =SUM(C7:C16) -> 326700 | D18: =SUM(D7:D16) -> 260150 | E18: =SUM(E7:E16) -> 371800 | F18: =SUM(F7:F16) -> 276650 | G18: =SUM(G7:G16) -> 342100 | H18: =SUM(H7:H16) -> 1577400

Sheet 📋 Assumptions
B5: ▌ REVENUE ASSUMPTIONS
B6: ASSUMPTION | C6: VALUE | D6: FORMAT | E6: NOTES
B7: Annual Revenue Growth | C7: 0.08 | D7: 0.0% | E7: Blended portfolio growth
B8: Rent Growth Rate | C8: 0.045 | D8: 0.0% | E8: Market rate increases
B9: Vacancy Rate | C9: 0.05 | D9: 0.0% | E9: Stabilized portfolio target
B10: Credit Loss Allowance | C10: 0.005 | D10: 0.0% | E10: % of gross potential rent
B13: ▌ EXPENSE ASSUMPTIONS
B14: ASSUMPTION | C14: VALUE | D14: FORMAT | E14: NOTES
B15: Operating Expense Ratio | C15: 0.36 | D15: 0.0% | E15: % of EGI
B16: Management Fee | C16: 0.05 | D16: 0.0% | E16: % of EGI
B17: Insurance Growth | C17: 0.06 | D17: 0.0% | E17: Annual increase
B18: Tax Assessment Growth | C18: 0.035 | D18: 0.0% | E18: Annual increase
B21: ▌ DEBT & FINANCING
B22: ASSUMPTION | C22: VALUE | D22: FORMAT | E22: NOTES
B23: Loan Amount | C23: 2000000 | D23: $#,##0 | E23: Primary mortgage
B24: Interest Rate | C24: 0.065 | D24: 0.000% | E24: Fixed rate
B25: Loan Term | C25: 30 | D25: @ | E25: Amortization period
B26: LTV Ratio | C26: 0.7 | D26: 0.0% | E26: Loan-to-value at origination
B29: ▌ VALUATION
B30: ASSUMPTION | C30: VALUE | D30: FORMAT | E30: NOTES
B31: Cap Rate (Stabilized) | C31: 6.50% | D31: 0.0% | E31: Market cap rate
B32: Price per Unit (Avg) | C32: $125,000 | D32: $#,##0 | E32: Current market
B33: Discount Rate (IRR) | C33: 12.0% | D33: 0.0% | E33: Target investor return
B34: Hold Period | C34: 5 yrs | D34: @ | E34: Investment horizon
B36: Expense Growth Rate | C36: 0.045 | E36: For forecasting model
B37: CapEx % of Revenue | C37: 0.03 | E37: CapEx as % of gross revenue
B38: Concessions (Annual) | C38: 2950 | E38: Total annual concessions
B40: ▌ OPERATING EXPENSE RATES
B41: Insurance (Annual) | C41: 8275 | E41: Fixed annual cost
B42: Property Taxes (Annual) | C42: 22066 | E42: Annual tax amount
B43: Maintenance % of EGI | C43: 0.08 | E43: % of EGI
B44: Utilities % of EGI | C44: 0.025 | E44: % of EGI
B45: Administrative % of EGI | C45: 0.018 | E45: % of EGI

Sheet 💵 Operating Cash Flow
B5: LINE ITEM | C5: Q1 2024 | D5: Q2 2024 | E5: Q3 2024 | F5: Q4 2024 | G5: FY 2024
B6: NET INCOME | C6: 48 | D6: 68 | E6: 98 | F6: 138 | G6: =C6+D6+E6+F6 -> 352
B7: Depreciation & Amort. | C7: 18 | D7: 18 | E7: 18 | F7: 18 | G7: =C7+D7+E7+F7 -> 72
B8: Amortization of Costs | C8: 3 | D8: 3 | E8: 3 | F8: 3 | G8: =C8+D8+E8+F8 -> 12
B9: FUNDS FROM OPERATIONS | C9: 69 | D9: 89 | E9: 119 | F9: 159 | G9: =C9+D9+E9+F9 -> 436
B10: (Increase) in A/R | C10: -5 | D10: -8 | E10: -4 | F10: -12 | G10: =C10+D10+E10+F10 -> -29
B11: (Increase) in Prepaid | C11: -2 | D11: -1 | E11: -3 | F11: -2 | G11: =C11+D11+E11+F11 -> -8
B12: Increase in A/P | C12: 8 | D12: 5 | E12: 11 | F12: 9 | G12: =C12+D12+E12+F12 -> 33
B13: Increase in Accruals | C13: 4 | D13: 6 | E13: 3 | F13: 8 | G13: =C13+D13+E13+F13 -> 21
B14: OPERATING CASH FLOW | C14: 74 | D14: 91 | E14: 126 | F14: 162 | G14: =C14+D14+E14+F14 -> 453
B15: CapEx | C15: =-'🏗️ Capital Plan'!C18/4 -> -81675 | D15: =-'🏗️ Capital Plan'!C18/4 -> -81675 | E15: =-'🏗️ Capital Plan'!C18/4 -> -81675 | F15: =-'🏗️ Capital Plan'!C18/4 -> -81675 | G15: =C15+D15+E15+F15 -> -326700
B16: Acquisitions | C16: 0 | D16: 0 | E16: 0 | F16: 0 | G16: =C16+D16+E16+F16 -> 0
B17: INVESTING CASH FLOW | C17: -22 | D17: -28 | E17: -35 | F17: -42 | G17: =C17+D17+E17+F17 -> -127
B18: Debt Repayment | C18: =-'💳 Amortization'!F11 -> -12641.36 | D18: =-'💳 Amortization'!F11 -> -12641.36 | E18: =-'💳 Amortization'!F11 -> -12641.36 | F18: =-'💳 Amortization'!F11 -> -12641.36 | G18: =C18+D18+E18+F18 -> -50565.442
B19: Distributions | C19: -10 | D19: -15 | E19: -20 | F19: -25 | G19: =C19+D19+E19+F19 -> -70
B20: FINANCING CASH FLOW | C20: -48 | D20: -53 | E20: -58 | F20: -63 | G20: =C20+D20+E20+F20 -> -222
B21: NET CHANGE IN CASH | C21: 4 | D21: 10 | E21: 33 | F21: 57 | G21: =C21+D21+E21+F21 -> 104
B22: ENDING CASH BALANCE | C22: 158 | D22: 168 | E22: 201 | F22: 258 | G22: =C22+D22+E22+F22 -> 785

Sheet 📥 Data Pulls
B2: KPI SUMMARY
B3: METRIC | C3: ACTUAL | D3: BUDGET / TARGET
B4: NOI | C4: ='⚙️ NOI Engine'!J18 -> 180249.6 | D4: =SUM(G59:G70) -> 0
B5: DSCR | C5: =IFERROR('⚙️ NOI Engine'!J18/ABS('⚙️ NOI Engine'!J19),0) -> 1.1858214 | D5: 1.25
B6: OCCUPANCY | C6: ='🏢 Property Metrics'!D12 -> 0.96084337 | D6: 0.95
B7: CASH FLOW | C7: ='⚙️ NOI Engine'!J20 -> 28245.6 | D7: 158000
B8: GROSS REV | C8: ='⚙️ NOI Engine'!J6 -> 297415 | D8: 280000
B9: NET INCOME | C9: ='💵 Operating Cash Flow'!F6 -> 138 | D9: 0.18
B11: ACTUAL MONTHLY SERIES — JAN–DEC 2024
B12: MONTH | C12: GROSS RENT | D12: VACANCY | E12: EGI | F12: OP EXP (ACTUAL) | G12: NOI | H12: DEBT SVC | I12: CASH FLOW | J12: OCCUPANCY | K12: DSCR
B13: Jan-24 | C13: 24583 | D13: 1425 | E13: =C13-D13 -> 23158 | F13: =E13*'📋 Assumptions'!C15 -> 8336.88 | G13: =E13-F13 -> 14821.12 | H13: 12667 | I13: =G13-H13 -> 2154.12 | J13: =IFERROR(1-(D13/C13),0) -> 0.94203311 | K13: =IFERROR(G13/H13,0) -> 1.1700576
B14: Feb-24 | C14: 24100 | D14: 1800 | E14: =C14-D14 -> 22300 | F14: =E14*'📋 Assumptions'!C15 -> 8028 | G14: =E14-F14 -> 14272 | H14: 12667 | I14: =G14-H14 -> 1605 | J14: =IFERROR(1-(D14/C14),0) -> 0.9253112 | K14: =IFERROR(G14/H14,0) -> 1.1267072
B15: Mar-24 | C15: 24583 | D15: 1425 | E15: =C15-D15 -> 23158 | F15: =E15*'📋 Assumptions'!C15 -> 8336.88 | G15: =E15-F15 -> 14821.12 | H15: 12667 | I15: =G15-H15 -> 2154.12 | J15: =IFERROR(1-(D15/C15),0) -> 0.94203311 | K15: =IFERROR(G15/H15,0) -> 1.1700576
B16: Apr-24 | C16: 24583 | D16: 1425 | E16: =C16-D16 -> 23158 | F16: =E16*'📋 Assumptions'!C15 -> 8336.88 | G16: =E16-F16 -> 14821.12 | H16: 12667 | I16: =G16-H16 -> 2154.12 | J16: =IFERROR(1-(D16/C16),0) -> 0.94203311 | K16: =IFERROR(G16/H16,0) -> 1.1700576
B17: May-24 | C17: 24900 | D17: 1200 | E17: =C17-D17 -> 23700 | F17: =E17*'📋 Assumptions'!C15 -> 8532 | G17: =E17-F17 -> 15168 | H17: 12667 | I17: =G17-H17 -> 2501 | J17: =IFERROR(1-(D17/C17),0) -> 0.95180723 | K17: =IFERROR(G17/H17,0) -> 1.1974422
B18: Jun-24 | C18: 25200 | D18: 1000 | E18: =C18-D18 -> 24200 | F18: =E18*'📋 Assumptions'!C15 -> 8712 | G18: =E18-F18 -> 15488 | H18: 12667 | I18: =G18-H18 -> 2821 | J18: =IFERROR(1-(D18/C18),0) -> 0.96031746 | K18: =IFERROR(G18/H18,0) -> 1.2227047
B19: Jul-24 | C19: 25200 | D19: 1000 | E19: =C19-D19 -> 24200 | F19: =E19*'📋 Assumptions'!C15 -> 8712 | G19: =E19-F19 -> 15488 | H19: 12667 | I19: =G19-H19 -> 2821 | J19: =IFERROR(1-(D19/C19),0) -> 0.96031746 | K19: =IFERROR(G19/H19,0) -> 1.2227047
B20: Aug-24 | C20: 25200 | D20: 1000 | E20: =C20-D20 -> 24200 | F20: =E20*'📋 Assumptions'!C15 -> 8712 | G20: =E20-F20 -> 15488 | H20: 12667 | I20: =G20-H20 -> 2821 | J20: =IFERROR(1-(D20/C20),0) -> 0.96031746 | K20: =IFERROR(G20/H20,0) -> 1.2227047
B21: Sep-24 | C21: 25000 | D21: 1250 | E21: =C21-D21 -> 23750 | F21: =E21*'📋 Assumptions'!C15 -> 8550 | G21: =E21-F21 -> 15200 | H21: 12667 | I21: =G21-H21 -> 2533 | J21: =IFERROR(1-(D21/C21),0) -> 0.95 | K21: =IFERROR(G21/H21,0) -> 1.1999684
B22: Oct-24 | C22: 24900 | D22: 1400 | E22: =C22-D22 -> 23500 | F22: =E22*'📋 Assumptions'!C15 -> 8460 | G22: =E22-F22 -> 15040 | H22: 12667 | I22: =G22-H22 -> 2373 | J22: =IFERROR(1-(D22/C22),0) -> 0.9437751 | K22: =IFERROR(G22/H22,0) -> 1.1873372
B23: Nov-24 | C23: 24583 | D23: 1425 | E23: =C23-D23 -> 23158 | F23: =E23*'📋 Assumptions'!C15 -> 8336.88 | G23: =E23-F23 -> 14821.12 | H23: 12667 | I23: =G23-H23 -> 2154.12 | J23: =IFERROR(1-(D23/C23),0) -> 0.94203311 | K23: =IFERROR(G23/H23,0) -> 1.1700576
B24: Dec-24 | C24: 24583 | D24: 1425 | E24: =C24-D24 -> 23158 | F24: =E24*'📋 Assumptions'!C15 -> 8336.88 | G24: =E24-F24 -> 14821.12 | H24: 12667 | I24: =G24-H24 -> 2154.12 | J24: =IFERROR(1-(D24/C24),0) -> 0.94203311 | K24: =IFERROR(G24/H24,0) -> 1.1700576
B26: BUDGET MONTHLY SERIES — JAN–DEC 2024
B27: MONTH | C27: GROSS RENT | D27: VACANCY | E27: EGI | F27: OP EXP | G27: NOI | H27: DEBT SVC | I27: CASH FLOW | J27: OCCUPANCY | K27: DSCR
B28: Jan-24 | C28: 25000 | D28: 1000 | E28: 24000 | F28: 8640 | G28: 15360 | H28: 12667 | I28: 2693 | J28: 0.96 | K28: 1.2125997
B29: Feb-24 | C29: 25000 | D29: 1000 | E29: 24000 | F29: 8640 | G29: 15360 | H29: 12667 | I29: 2693 | J29: 0.96 | K29: 1.2125997
B30: Mar-24 | C30: 25000 | D30: 1000 | E30: 24000 | F30: 8640 | G30: 15360 | H30: 12667 | I30: 2693 | J30: 0.96 | K30: 1.2125997
B31: Apr-24 | C31: 25000 | D31: 1000 | E31: 24000 | F31: 8640 | G31: 15360 | H31: 12667 | I31: 2693 | J31: 0.96 | K31: 1.2125997
B32: May-24 | C32: 25000 | D32: 1000 | E32: 24000 | F32: 8640 | G32: 15360 | H32: 12667 | I32: 2693 | J32: 0.96 | K32: 1.2125997
B33: Jun-24 | C33: 25000 | D33: 1000 | E33: 24000 | F33: 8640 | G33: 15360 | H33: 12667 | I33: 2693 | J33: 0.96 | K33: 1.2125997
B34: Jul-24 | C34: 25000 | D34: 1000 | E34: 24000 | F34: 8640 | G34: 15360 | H34: 12667 | I34: 2693 | J34: 0.96 | K34: 1.2125997
B35: Aug-24 | C35: 25000 | D35: 1000 | E35: 24000 | F35: 8640 | G35: 15360 | H35: 12667 | I35: 2693 | J35: 0.96 | K35: 1.2125997
B36: Sep-24 | C36: 25000 | D36: 1000 | E36: 24000 | F36: 8640 | G36: 15360 | H36: 12667 | I36: 2693 | J36: 0.96 | K36: 1.2125997
B37: Oct-24 | C37: 25000 | D37: 1000 | E37: 24000 | F37: 8640 | G37: 15360 | H37: 12667 | I37: 2693 | J37: 0.96 | K37: 1.2125997
B38: Nov-24 | C38: 25000 | D38: 1000 | E38: 24000 | F38: 8640 | G38: 15360 | H38: 12667 | I38: 2693 | J38: 0.96 | K38: 1.2125997
B39: Dec-24 | C39: 25000 | D39: 1000 | E39: 24000 | F39: 8640 | G39: 15360 | H39: 12667 | I39: 2693 | J39: 0.96 | K39: 1.2125997
B40: TOTAL / ANNUAL | C40: 300000 | D40: 12000 | E40: 288000 | F40: 103680 | G40: 184320 | H40: 152004 | I40: 32316 | J40: 0.96 | K40: 1.2125997
B42: PROPERTY SNAPSHOT
B43: PROPERTY | C43: OCCUPANCY | D43: NOI | E43: DSCR | F43: RENT | G43: CASH FLOW | H43: CAP RATE | I43: STATUS
B44: The Meridian | C44: ='🏢 Property Metrics'!D7 -> 0.9375 | D44: ='🏢 Property Metrics'!I7 -> 25200 | E44: ='🏢 Property Metrics'!C7 -> 1.35 | F44: ='🏢 Property Metrics'!E7 -> 42000 | G44: ='🏢 Property Metrics'!K7 -> 6533.3333 | H44: ='🏢 Property Metrics'!J7 -> 0.062 | I44: STABLE
...

Sheet 🚀 DISPATCH
B2: KPI SUMMARY
B3: METRIC | C3: ACTUAL | D3: BUDGET / TARGET
B4: NOI | C4: 280249.6 | D4: 0
B5: DSCR | C5: 2.1858214 | D5: 1.25
B6: OCCUPANCY | C6: 0.26084337 | D6: 0.95
B7: CASH FLOW | C7: 28245.6 | D7: 158000
B8: GROSS REV | C8: 297415 | D8: 280000
B9: NET INCOME | C9: 238000 | D9: 0.18
B11: ACTUAL MONTHLY SERIES — JAN–DEC 2024
B12: MONTH | C12: GROSS RENT | D12: VACANCY | E12: EGI | F12: OP EXP (ACTUAL) | G12: NOI | H12: DEBT SVC | I12: CASH FLOW | J12: OCCUPANCY | K12: DSCR
B13: Jan-24 | C13: 24583 | D13: 1425 | E13: 23158 | F13: 8336.88 | G13: 14821.12 | H13: 12667 | I13: 2154.12 | J13: 0.94203311 | K13: 1.1700576
B14: Feb-24 | C14: 24100 | D14: 1800 | E14: 22300 | F14: 8028 | G14: 14272 | H14: 12667 | I14: 1605 | J14: 0.9253112 | K14: 1.1267072
B15: Mar-24 | C15: 24583 | D15: 1425 | E15: 23158 | F15: 8336.88 | G15: 14821.12 | H15: 12667 | I15: 2154.12 | J15: 0.94203311 | K15: 1.1700576
B16: Apr-24 | C16: 24583 | D16: 1425 | E16: 23158 | F16: 8336.88 | G16: 14821.12 | H16: 12667 | I16: 2154.12 | J16: 0.94203311 | K16: 1.1700576
B17: May-24 | C17: 24900 | D17: 1200 | E17: 23700 | F17: 8532 | G17: 15168 | H17: 12667 | I17: 2501 | J17: 0.95180723 | K17: 1.1974422
B18: Jun-24 | C18: 25200 | D18: 1000 | E18: 24200 | F18: 8712 | G18: 15488 | H18: 12667 | I18: 2821 | J18: 0.96031746 | K18: 1.2227047
B19: Jul-24 | C19: 25200 | D19: 1000 | E19: 24200 | F19: 8712 | G19: 15488 | H19: 12667 | I19: 2821 | J19: 0.96031746 | K19: 1.2227047
B20: Aug-24 | C20: 25200 | D20: 1000 | E20: 24200 | F20: 8712 | G20: 15488 | H20: 12667 | I20: 2821 | J20: 0.96031746 | K20: 1.2227047
B21: Sep-24 | C21: 25000 | D21: 1250 | E21: 23750 | F21: 8550 | G21: 15200 | H21: 12667 | I21: 2533 | J21: 0.95 | K21: 1.1999684
B22: Oct-24 | C22: 24900 | D22: 1400 | E22: 23500 | F22: 8460 | G22: 15040 | H22: 12667 | I22: 2373 | J22: 0.9437751 | K22: 1.1873372
B23: Nov-24 | C23: 24583 | D23: 1425 | E23: 23158 | F23: 8336.88 | G23: 14821.12 | H23: 12667 | I23: 2154.12 | J23: 0.94203311 | K23: 1.1700576
B24: Dec-24 | C24: 24583 | D24: 1425 | E24: 23158 | F24: 8336.88 | G24: 14821.12 | H24: 12667 | I24: 2154.12 | J24: 0.94203311 | K24: 1.1700576
B26: BUDGET MONTHLY SERIES — JAN–DEC 2024
B27: MONTH | C27: GROSS RENT | D27: VACANCY | E27: EGI | F27: OP EXP | G27: NOI | H27: DEBT SVC | I27: CASH FLOW | J27: OCCUPANCY | K27: DSCR
B28: Jan-24 | C28: 25000 | D28: 1000 | E28: 24000 | F28: 8640 | G28: 15360 | H28: 12667 | I28: 2693 | J28: 0.96 | K28: 1.2125997
B29: Feb-24 | C29: 25000 | D29: 1000 | E29: 24000 | F29: 8640 | G29: 15360 | H29: 12667 | I29: 2693 | J29: 0.96 | K29: 1.2125997
B30: Mar-24 | C30: 25000 | D30: 1000 | E30: 24000 | F30: 8640 | G30: 15360 | H30: 12667 | I30: 2693 | J30: 0.96 | K30: 1.2125997
B31: Apr-24 | C31: 25000 | D31: 1000 | E31: 24000 | F31: 8640 | G31: 15360 | H31: 12667 | I31: 2693 | J31: 0.96 | K31: 1.2125997
B32: May-24 | C32: 25000 | D32: 1000 | E32: 24000 | F32: 8640 | G32: 15360 | H32: 12667 | I32: 2693 | J32: 0.96 | K32: 1.2125997
B33: Jun-24 | C33: 25000 | D33: 1000 | E33: 24000 | F33: 8640 | G33: 15360 | H33: 12667 | I33: 2693 | J33: 0.96 | K33: 1.2125997
B34: Jul-24 | C34: 25000 | D34: 1000 | E34: 24000 | F34: 8640 | G34: 15360 | H34: 12667 | I34: 2693 | J34: 0.96 | K34: 1.2125997
B35: Aug-24 | C35: 25000 | D35: 1000 | E35: 24000 | F35: 8640 | G35: 15360 | H35: 12667 | I35: 2693 | J35: 0.96 | K35: 1.2125997
B36: Sep-24 | C36: 25000 | D36: 1000 | E36: 24000 | F36: 8640 | G36: 15360 | H36: 12667 | I36: 2693 | J36: 0.96 | K36: 1.2125997
B37: Oct-24 | C37: 25000 | D37: 1000 | E37: 24000 | F37: 8640 | G37: 15360 | H37: 12667 | I37: 2693 | J37: 0.96 | K37: 1.2125997
B38: Nov-24 | C38: 25000 | D38: 1000 | E38: 24000 | F38: 8640 | G38: 15360 | H38: 12667 | I38: 2693 | J38: 0.96 | K38: 1.2125997
B39: Dec-24 | C39: 25000 | D39: 1000 | E39: 24000 | F39: 8640 | G39: 15360 | H39: 12667 | I39: 2693 | J39: 0.96 | K39: 1.2125997
B40: TOTAL / ANNUAL | C40: 300000 | D40: 12000 | E40: 288000 | F40: 103680 | G40: 184320 | H40: 152004 | I40: 32316 | J40: 0.96 | K40: 1.2125997
B42: PROPERTY SNAPSHOT
B43: PROPERTY | C43: OCCUPANCY | D43: NOI | E43: DSCR | F43: RENT | G43: CASH FLOW | H43: CAP RATE | I43: STATUS
B44: The Meridian | C44: 0.9375 | D44: 25200 | E44: 1.35 | F44: 42000 | G44: 6533.3333 | H44: 0.062 | I44: STABLE
...
